Workbook

Sheet README
A1: SGR EXECUTIVE DASHBOARD | CONTROL CENTRE
A3: =HYPERLINK("#'HOME'!A1","HOME") -> HOME | B3: =HYPERLINK("#'FARMERS'!A1","FARMERS") -> FARMERS | C3: =HYPERLINK("#'SUBSCRIPTIONS'!A1","SUBSCRIPTIONS") -> SUBSCRIPTIONS | D3: =HYPERLINK("#'PRODUCTION'!A1","PRODUCTION") -> PRODUCTION | E3: =HYPERLINK("#'RECOVERY'!A1","RECOVERY") -> RECOVERY | F3: =HYPERLINK("#'DELIVERIES'!A1","DELIVERIES") -> DELIVERIES | G3: =HYPERLINK("#'FINANCE'!A1","FINANCE") -> FINANCE | H3: =HYPERLINK("#'REPORTS'!A1","REPORTS") -> REPORTS | I3: =HYPERLINK("#'SORGHUM BUDGET'!A1","SORGHUM BUDGET") -> SORGHUM BUDGET | J3: =HYPERLINK("#'MAIZE BUDGET'!A1","MAIZE BUDGET") -> MAIZE BUDGET

Sheet HOME
A1: STRATEGIC GRAIN RESERVE (SGR) 200 HA PLUS
A2: Executive Management Dashboard | Data snapshot through August 2026
A3: =HYPERLINK("#'HOME'!A1","HOME") -> HOME | B3: =HYPERLINK("#'FARMERS'!A1","FARMERS") -> FARMERS | C3: =HYPERLINK("#'SUBSCRIPTIONS'!A1","SUBSCRIPTIONS") -> SUBSCRIPTIONS | D3: =HYPERLINK("#'PRODUCTION'!A1","PRODUCTION") -> PRODUCTION | E3: =HYPERLINK("#'RECOVERY'!A1","RECOVERY") -> RECOVERY | F3: =HYPERLINK("#'DELIVERIES'!A1","DELIVERIES") -> DELIVERIES | G3: =HYPERLINK("#'FINANCE'!A1","FINANCE") -> FINANCE | H3: =HYPERLINK("#'REPORTS'!A1","REPORTS") -> REPORTS | J3: =HYPERLINK("#'MONTHLY SALARY'!A1","MONTHLY SALARY") -> MONTHLY SALARY | K3: =HYPERLINK("#'PROFIT & LOSS'!A1","PROFIT & LOSS") -> PROFIT & LOSS | L3: =HYPERLINK("#'BALANCE SHEET'!A1","BALANCE SHEET") -> BALANCE SHEET
A4: EXECUTIVE PERFORMANCE AT A GLANCE
A5: REGISTERED FARMERS | C5: PAID FARMERS | E5: PARTLY PAID FARMERS | G5: TOTAL SUBSCRIBED | I5: SUBSCRIPTION RATE | K5: SUBSCRIPTIONS RECEIVED
A6: =COUNTA(DATA_PIPELINE!$B$6:$B$601) -> 573 | C6: =COUNTIF(DATA_PIPELINE!$Y$6:$Y$601,"Paid") -> 18 | E6: =COUNTIF(DATA_PIPELINE!$Y$6:$Y$601,"Partly Paid") -> 38 | G6: =C6+E6 -> 56 | I6: =IFERROR(G6/A6,0) -> 0.097731239 | K6: =SUM(DATA_RECEIPTS!$E$6:$E$75) -> 17375
A7: TOTAL MEMBERS | C7: PAID | E7: PARTLY PAID | G7: PAID + PARTLY PAID | I7: REGISTERED | K7: TO DATE
A10: MAIZE TARGET | C10: MAIZE COMMITTED HA | E10: MAIZE VARIANCE | G10: SORGHUM TARGET | I10: SORGHUM COMMITTED HA | K10: SORGHUM VARIANCE
A11: 20000 | C11: =SUMIFS(DATA_PIPELINE!$M$6:$M$601,DATA_PIPELINE!$Y$6:$Y$601,"Paid")+SUMIFS(DATA_PIPELINE!$M$6:$M$601,DATA_PIPELINE!$Y$6:$Y$601,"Partly Paid") -> 1950 | E11: =C11-A11 -> -18050 | G11: 20000 | I11: =SUMIFS(DATA_PIPELINE!$N$6:$N$601,DATA_PIPELINE!$Y$6:$Y$601,"Paid")+SUMIFS(DATA_PIPELINE!$N$6:$N$601,DATA_PIPELINE!$Y$6:$Y$601,"Partly Paid") -> 5265 | K11: =I11-G11 -> -14735
A12: TARGET ACHIEVEMENT | C12: =IFERROR(C11/A11,0) -> 0.0975 | E12: TARGET GAP | G12: TARGET ACHIEVEMENT | I12: 0.195 | K12: TARGET GAP
A15: YTD RECEIPTS STATUS | C15: TOTAL RECEIPTS | E15: SEPTEMBER TOTAL RECEIPTS | G15: BANK BALANCE | I15: SUBSCRIPTION OUTSTANDING | K15: LAST DATA REFRESH
A16: =TODAY() -> 46295 | C16: =SUM(DATA_BANK!$C$6:$C$10) -> 17375 | E16: =SUMIFS(DATA_RECEIPTS!E:E, DATA_RECEIPTS!A:A, ">=2026-09-01", DATA_RECEIPTS!A:A, "<2026-10-01") -> 2725 | G16: =DATA_BANK!E10 -> 4125.12 | I16: =SUM(DATA_RECEIPTS!$F$6:$F$75) -> 14025 | K16: =TODAY() -> 46295
A20: Management navigation
A21: =HYPERLINK("#'FARMERS'!A1","Farmers") -> Farmers | C21: =HYPERLINK("#'SUBSCRIPTIONS'!A1","Subscriptions") -> Subscriptions | E21: =HYPERLINK("#'PRODUCTION'!A1","Production") -> Production | G21: =HYPERLINK("#'RECOVERY'!A1","Recovery Programme") -> Recovery Programme | I21: =HYPERLINK("#'DELIVERIES'!A1","Grain Deliveries") -> Grain Deliveries | K21: =HYPERLINK("#'FINANCE'!A1","Finance") -> Finance
A24: =HYPERLINK("#'REPORTS'!A1","Reports") -> Reports | C24: =HYPERLINK("#'DATA_PIPELINE'!A1","Data Pipeline") -> Data Pipeline | E24: =HYPERLINK("#'DATA_RECOVERY'!A1","Data Recovery") -> Data Recovery | G24: =HYPERLINK("#'DATA_RECEIPTS'!A1","Data Receipts") -> Data Receipts | I24: =HYPERLINK("#'DATA_EXPENSES'!A1","Data Expenses") -> Data Expenses | K24: =HYPERLINK("#'DATA_BANK'!A1","Data Bank") -> Data Bank
A27: SORGHUM 20,000 HA | PLANTING BUDGET CONTROL
A29: PAID MEMBERS | D29: PAID SORGHUM HA | G29: FUNDED HA | J29: 20,000 HA TARGET | M29: HA REMAINING
A30: =COUNTIF(DATA_PIPELINE!$Y$6:$Y$601,"Paid")+COUNTIF(DATA_PIPELINE!$Y$6:$Y$601,"Partly Paid") -> 56 | D30: =SUMIFS(DATA_PIPELINE!$N$6:$N$601,DATA_PIPELINE!$Y$6:$Y$601,"Paid")+SUMIFS(DATA_PIPELINE!$N$6:$N$601,DATA_PIPELINE!$Y$6:$Y$601,"Partly Paid") -> 5265 | G30: =MIN(D30,J30) -> 5265 | J30: =20000 -> 20000 | M30: =MAX(0,J30-G30) -> 14735
A32: COST / HA (HIRING) | D32: TOTAL COST | 20,000 HA | G32: BUDGET | FUNDED HA | J32: BUDGET REMAINING | M32: TARGET FUNDED %
A33: ='SORGHUM BUDGET'!I38 -> 873 | D33: =J30*A33 -> 17460000 | G33: =G30*A33 -> 4596345 | J33: =MAX(0,D33-G33) -> 12863655 | M33: =IFERROR(G30/J30,0) -> 0.26325
A35: BUDGET BREAKDOWN BY COST GROUP | G35: MANAGEMENT VIEW
A36: Cost Group | B36: Cost / Ha | C36: Cost @ 20,000 HA | D36: Cost @ Funded HA | E36: Share of Total
A37: Seed | B37: ='SORGHUM BUDGET'!I10+'SORGHUM BUDGET'!I11 -> 50 | C37: =B37*$J$30 -> 1000000 | D37: =B37*$G$30 -> 263250 | E37: =IFERROR(B37/$A$33,0) -> 0.057273769 | G37: Budget cost / ha | I37: ='SORGHUM BUDGET'!I38 -> 873
A38: Fertilisers | B38: ='SORGHUM BUDGET'!I14+'SORGHUM BUDGET'!I15 -> 268 | C38: =B38*$J$30 -> 5360000 | D38: =B38*$G$30 -> 1411020 | E38: =IFERROR(B38/$A$33,0) -> 0.3069874 | G38: Base source cost / ha | I38: ='SORGHUM BUDGET'!H38 -> 743
A39: Tillage | B39: ='SORGHUM BUDGET'!I18+'SORGHUM BUDGET'!I19+'SORGHUM BUDGET'!I20 -> 220 | C39: =B39*$J$30 -> 4400000 | D39: =B39*$G$30 -> 1158300 | E39: =IFERROR(B39/$A$33,0) -> 0.25200458 | G39: Paid members | I39: =COUNTIF(DATA_PIPELINE!$Y$6:$Y$601,"Paid")+COUNTIF(DATA_PIPELINE!$Y$6:$Y$601,"Partly Paid") -> 56
A40: Chemicals - Pre-emergence Herbicides | B40: ='SORGHUM BUDGET'!I24+'SORGHUM BUDGET'!I25+'SORGHUM BUDGET'!I26 -> 32 | C40: =B40*$J$30 -> 640000 | D40: =B40*$G$30 -> 168480 | E40: =IFERROR(B40/$A$33,0) -> 0.036655212 | G40: Paid sorghum hectares | I40: =SUMIFS(DATA_PIPELINE!$N$6:$N$601,DATA_PIPELINE!$Y$6:$Y$601,"Paid")+SUMIFS(DATA_PIPELINE!$N$6:$N$601,DATA_PIPELINE!$Y$6:$Y$601,"Partly Paid") -> 5265
A41: Chemicals - Post-emergence Herbicides | B41: ='SORGHUM BUDGET'!I28+'SORGHUM BUDGET'!I29 -> 15 | C41: =B41*$J$30 -> 300000 | D41: =B41*$G$30 -> 78975 | E41: =IFERROR(B41/$A$33,0) -> 0.017182131 | G41: Funded hectares (capped) | I41: =G30 -> 5265
A42: Chemicals - Insecticides / Fungicides | B42: ='SORGHUM BUDGET'!I31+'SORGHUM BUDGET'!I32+'SORGHUM BUDGET'!I33 -> 18 | C42: =B42*$J$30 -> 360000 | D42: =B42*$G$30 -> 94770 | E42: =IFERROR(B42/$A$33,0) -> 0.020618557 | G42: Funding gap to 20,000 HA | I42: =MAX(0,J30-G30) -> 14735
A43: Packaging | B43: ='SORGHUM BUDGET'!I34 -> 20 | C43: =B43*$J$30 -> 400000 | D43: =B43*$G$30 -> 105300 | E43: =IFERROR(B43/$A$33,0) -> 0.022909507 | G43: Budget for funded hectares | I43: =G33 -> 4596345
A44: Combine | B44: ='SORGHUM BUDGET'!I35 -> 90 | C44: =B44*$J$30 -> 1800000 | D44: =B44*$G$30 -> 473850 | E44: =IFERROR(B44/$A$33,0) -> 0.10309278 | G44: Budget for full 20,000 HA | I44: =D33 -> 17460000
A45: Labour | B45: ='SORGHUM BUDGET'!I36 -> 80 | C45: =B45*$J$30 -> 1600000 | D45: =B45*$G$30 -> 421200 | E45: =IFERROR(B45/$A$33,0) -> 0.09163803 | G45: Budget sheet
A46: Transport | B46: ='SORGHUM BUDGET'!I37 -> 80 | C46: =B46*$J$30 -> 1600000 | D46: =B46*$G$30 -> 421200 | E46: =IFERROR(B46/$A$33,0) -> 0.09163803
A47: TOTAL | B47: =SUM(B37:B46) -> 873 | C47: =SUM(C37:C46) -> 17460000 | D47: =SUM(D37:D46) -> 4596345 | E47: =SUM(E37:E46) -> 1
A50: MAIZE 20,000 HA | PLANTING BUDGET CONTROL
A52: PAID MEMBERS | D52: PAID MAIZE HA | G52: FUNDED HA | J52: 20,000 HA TARGET | M52: HA REMAINING
A53: =COUNTIF(DATA_PIPELINE!$Y$6:$Y$601,"Paid")+COUNTIF(DATA_PIPELINE!$Y$6:$Y$601,"Partly Paid") -> 56 | D53: =SUMIFS(DATA_PIPELINE!$M$6:$M$601,DATA_PIPELINE!$Y$6:$Y$601,"Paid")+SUMIFS(DATA_PIPELINE!$M$6:$M$601,DATA_PIPELINE!$Y$6:$Y$601,"Partly Paid") -> 1950 | G53: =MIN(D53,J53) -> 1950 | J53: =20000 -> 20000 | M53: =MAX(0,J53-G53) -> 18050
A55: COST / HA (HIRING) | D55: TOTAL COST | 20,000 HA | G55: BUDGET | FUNDED HA | J55: BUDGET REMAINING | M55: TARGET FUNDED %
A56: ='MAIZE BUDGET'!E49 -> 1119.825 | D56: =J53*A56 -> 22396500 | G56: =G53*A56 -> 2183658.8 | J56: =MAX(0,D56-G56) -> 20212841 | M56: =IFERROR(G53/J53,0) -> 0.0975
A58: BUDGET BREAKDOWN BY COST GROUP | G58: MANAGEMENT VIEW
A59: Cost Group | B59: Cost / Ha | C59: Cost @ 20,000 HA | D59: Cost @ Funded HA | E59: Share of Total | G59: Budget cost / ha | I59: ='MAIZE BUDGET'!E49 -> 1119.825
...

Sheet SORGHUM BUDGET
A1: =HYPERLINK("#'HOME'!A1","HOME") -> HOME | B1: =HYPERLINK("#'SORGHUM BUDGET'!A1","SORGHUM BUDGET") -> SORGHUM BUDGET | C1: =HYPERLINK("#'PRODUCTION'!A1","PRODUCTION") -> PRODUCTION | D1: =HYPERLINK("#'SUBSCRIPTIONS'!A1","SUBSCRIPTIONS") -> SUBSCRIPTIONS
A2: SGR SORGHUM BUDGET 2026
A3: SORGHUM 20,000 HA | EXECUTIVE BUDGET MODEL
A5: SOURCE BUDGET INPUT (editable)
D9: Rate/Ha | E9: Unit | F9: Total Requirement | G9: Unit Cost | H9: Total Cost | I9: Total Cost Hiring
A10: Seed | B10: SCXH102/NS-5511 | D10: 10 | E10: Kg | F10: 1 | G10: 40 | H10: =F10*G10 -> 40 | I10: =H10 -> 40
B11: Seed Saffener | C11: Benoxacor | D11: 0.06 | E11: kg | F11: 1 | G11: 10 | H11: =F11*G11 -> 10 | I11: =H11 -> 10
I12: =H12 -> 0
A13: Fertilisers | I13: =H13 -> 0
B14: Basal fertiliser | D14: 200 | E14: kg | F14: =D14/50 -> 4 | G14: 32 | H14: =F14*G14 -> 128 | I14: =H14 -> 128
B15: Top Dressing | D15: 200 | E15: kg | F15: =D15/50 -> 4 | G15: 35 | H15: =F15*G15 -> 140 | I15: =H15 -> 140
I16: =H16 -> 0
A17: Tillage | I17: =H17 -> 0
A18: Discing | B18: Fuel | D18: 20 | E18: l | F18: 1 | G18: 2 | H18: 40 | I18: =50+40 -> 90
A19: Planting | B19: Fuel | D19: 15 | E19: l | F19: 1 | G19: 2 | H19: 30 | I19: =40+30 -> 70
A20: Spraying and fertilisation(7 times) | B20: Fuel | D20: 5 | E20: l | F20: 2 | G20: 2 | H20: 20 | I20: =20+40 -> 60
I21: =H21 -> 0
A22: Chemicals | I22: =H22 -> 0
A23: Pre-emergence Herbicides | C23: Weeds Controlled | I23: =H23 -> 0
B24: Glyphostae(granules) | C24: All | D24: 2 | E24: Kg | F24: 2 | G24: 6 | H24: 12 | I24: =H24 -> 12
B25: S-Metolachlor | C25: Broadleaf/grasses | D25: 1.2 | E25: L | F25: 1.2 | G25: 10 | H25: 12 | I25: =H25 -> 12
B26: Atrazine | C26: Annual Broadleaf | D26: 2 | E26: L | F26: 2 | G26: 4 | H26: 8 | I26: =H26 -> 8
A27: Post Emergence Herbicides | I27: =H27 -> 0
B28: Atrazine | C28: Broadleaf weeds | D28: 3 | E28: L | F28: 1 | G28: 4 | H28: 12 | I28: =H28 -> 12
B29: CP Wetter | C29: sticker / adjuvant | D29: 0.3 | E29: L | F29: 0.3 | G29: 3 | H29: 3 | I29: =H29 -> 3
A30: Insecticides | I30: =H30 -> 0
B31: Elegent Star | C31: Fall- armyworm | D31: 0.15 | E31: L | F31: 0.15 | G31: 8 | H31: 8 | I31: =H31 -> 8
B32: Dimethoate | C32: Aphids & leaf eaters | D32: 0.56 | E32: L | F32: 0.56 | G32: 8.9 | H32: 5 | I32: =H32 -> 5
B33: Tebiconazole | C33: Fungal Diseases | D33: 0.25 | E33: L | F33: 0.25 | G33: 5 | H33: 5 | I33: =H33 -> 5
A34: Packaging | C34: 4 tonnes per ha | D34: 80 | F34: 5 | G34: 4 | H34: 20 | I34: =H34 -> 20
A35: Combine | C35: dry rate | H35: 90 | I35: =H35 -> 90
A36: Labour days | C36: 20 labour days | D36: 5 | E36: days | F36: 4 | G36: 20 | H36: 80 | I36: =H36 -> 80
A37: Transport | C37: nearest gmb 0.15c/km /tonne | F37: 10 | G37: 8 | H37: 80 | I37: =H37 -> 80
A38: Total | H38: =SUM(H10:H37) -> 743 | I38: =SUM(I10:I37) -> 873
A46: EXECUTIVE COST GROUP DETAIL | HIRING RATES
A47: Group | B47: Item | C47: Rate/Ha | D47: Unit | E47: Cost/Ha | F47: Cost @20,000 HA | G47: Cost @ Funded HA | H47: Source Row
A48: Seed | B48: SCXH102/NS-5511 | C48: =D10 -> 10 | D48: =E10 -> Kg | E48: =I10 -> 40 | F48: =E48*20000 -> 800000 | G48: =E48*HOME!$G$30 -> 210600 | H48: 10
A49: Seed | B49: Seed Safener - Benoxacor | C49: =D11 -> 0.06 | D49: =E11 -> kg | E49: =I11 -> 10 | F49: =E49*20000 -> 200000 | G49: =E49*HOME!$G$30 -> 52650 | H49: 11
A50: Fertilisers | B50: Basal fertiliser | C50: =D14 -> 200 | D50: =E14 -> kg | E50: =I14 -> 128 | F50: =E50*20000 -> 2560000 | G50: =E50*HOME!$G$30 -> 673920 | H50: 14
A51: Fertilisers | B51: Top Dressing | C51: =D15 -> 200 | D51: =E15 -> kg | E51: =I15 -> 140 | F51: =E51*20000 -> 2800000 | G51: =E51*HOME!$G$30 -> 737100 | H51: 15
...

Sheet REPORTS
A1: MANAGEMENT REPORTS
A2: Print-ready A4 landscape report pages
A3: =HYPERLINK("#'HOME'!A1","HOME") -> HOME | B3: =HYPERLINK("#'FARMERS'!A1","FARMERS") -> FARMERS | C3: =HYPERLINK("#'SUBSCRIPTIONS'!A1","SUBSCRIPTIONS") -> SUBSCRIPTIONS | D3: =HYPERLINK("#'PRODUCTION'!A1","PRODUCTION") -> PRODUCTION | E3: =HYPERLINK("#'RECOVERY'!A1","RECOVERY") -> RECOVERY | F3: =HYPERLINK("#'DELIVERIES'!A1","DELIVERIES") -> DELIVERIES | G3: =HYPERLINK("#'FINANCE'!A1","FINANCE") -> FINANCE | H3: =HYPERLINK("#'REPORTS'!A1","REPORTS") -> REPORTS
A5: =HYPERLINK("#'HOME'!A1","Executive Summary Report") -> Executive Summary Report | D5: =HYPERLINK("#'FARMERS'!A1","Farmer Register") -> Farmer Register | G5: =HYPERLINK("#'SUBSCRIPTIONS'!A1","Subscription Report") -> Subscription Report | J5: =HYPERLINK("#'SORGHUM BUDGET'!A1","Sorghum 20,000 HA Budget") -> Sorghum 20,000 HA Budget
A8: =HYPERLINK("#'RECOVERY'!A1","Recovery Report") -> Recovery Report | D8: =HYPERLINK("#'DELIVERIES'!A1","Grain Delivery Report") -> Grain Delivery Report | G8: =HYPERLINK("#'FINANCE'!A1","Financial Report") -> Financial Report | J8: =HYPERLINK("#'FINANCE'!A1","Monthly Management Report") -> Monthly Management Report
J10: =HYPERLINK("#'MONTHLY SALARY'!A1","MONTHLY SALARY") -> MONTHLY SALARY
A11: =HYPERLINK("#'HOME'!A1","Annual Performance Report") -> Annual Performance Report | J11: =HYPERLINK("#'PROFIT & LOSS'!A1","PROFIT & LOSS") -> PROFIT & LOSS
J12: =HYPERLINK("#'BALANCE SHEET'!A1","BALANCE SHEET") -> BALANCE SHEET
A15: Printing setup
A16: All management dashboard sheets are configured for A4 landscape printing. Use File → Print → Print Active Sheets after selecting the desired dashboard/report.

Sheet DATA_PIPELINE
A1: DATA PIPELINE
A2: Imported source snapshot — update this table when source workbooks change.
A3: =HYPERLINK("#'HOME'!A1","HOME") -> HOME | B3: =HYPERLINK("#'FARMERS'!A1","FARMERS") -> FARMERS | C3: =HYPERLINK("#'SUBSCRIPTIONS'!A1","SUBSCRIPTIONS") -> SUBSCRIPTIONS | D3: =HYPERLINK("#'PRODUCTION'!A1","PRODUCTION") -> PRODUCTION | E3: =HYPERLINK("#'RECOVERY'!A1","RECOVERY") -> RECOVERY | F3: =HYPERLINK("#'DELIVERIES'!A1","DELIVERIES") -> DELIVERIES | G3: =HYPERLINK("#'FINANCE'!A1","FINANCE") -> FINANCE | H3: =HYPERLINK("#'REPORTS'!A1","REPORTS") -> REPORTS
A5: SEQ | B5: FARMER NAME | C5: FARM NAME | D5: CLUSTER | E5: ID NUMBER | F5: CONTACT | G5: DISTRCT | H5: PROVINCE | I5: WARD | J5: STATUS | K5: SUB PAID | L5: SUB BAL | M5: MAIZE (HA)-2026/27 | N5: SORGHUM (HA)-2026/27 | O5: TOTAL DEBT | P5: SORGHUM SOLD | Q5: SORGHUM VALUE | R5: BALANCE | S5: REPAYMENT (%) | T5: TOTAL CONTRACTED HA | U5: SUBSCRIPTION CATEGORY | V5: EXPECTED SUBSCRIPTION | W5: PAID AMOUNT | X5: OUTSTANDING | Y5: CALCULATED PAYMENT STATUS
A6: 1 | B6: BEHANE FLORENCE | C6: NK | D6: DANMORE MUDAVANHU | E6: 63-676409-M-39 | F6: 772816543 | G6: CHEGUTU | H6: MASHWEST | I6: 21 | J6: EXISTING | K6: 0 | L6: 0 | M6: 50 | N6: 50 | O6: 10273.28 | P6: 0 | Q6: 0 | R6: 10273.28 | S6: - | T6: 50 | U6: Category A | V6: 500 | W6: =DATA_PIPELINE!$K6 -> 0 | X6: =DATA_PIPELINE!$V6-DATA_PIPELINE!$W6 -> 500 | Y6: =IF(DATA_PIPELINE!$X6=0,"Paid",IF(DATA_PIPELINE!$W6=0,"Unpaid","Partly Paid")) -> Unpaid
A7: 2 | B7: ZINYOWERA DONALD | C7: UNIT 40 COBEN ESTATES | D7: DANMORE MUDAVANHU | E7: 63-259741-M-24 | F7: 774739609 | G7: CHEGUTU | H7: MASHWEST | J7: EXISTING | K7: 0 | L7: 0 | M7: 35 | N7: 50 | O7: 6466.9 | P7: 0 | Q7: 0 | R7: 6466.9 | S7: - | T7: 50 | U7: Category A | V7: 500 | W7: =DATA_PIPELINE!$K7 -> 0 | X7: =DATA_PIPELINE!$V7-DATA_PIPELINE!$W7 -> 500 | Y7: =IF(DATA_PIPELINE!$X7=0,"Paid",IF(DATA_PIPELINE!$W7=0,"Unpaid","Partly Paid")) -> Unpaid
A8: 3 | B8: MUNEMO MOSES | C8: AVOG 8 A COBURN ESTSTES | D8: DANMORE MUDAVANHU | E8: 63-431627-V-25 | F8: 771487499 | G8: CHEGUTU | H8: MASHWEST | J8: EXISTING | K8: 0 | L8: 0 | M8: 40 | N8: 40 | O8: 7596.28 | P8: 0 | Q8: 0 | R8: 7596.28 | S8: - | T8: 40 | U8: Category A | V8: 500 | W8: =DATA_PIPELINE!$K8 -> 0 | X8: =DATA_PIPELINE!$V8-DATA_PIPELINE!$W8 -> 500 | Y8: =IF(DATA_PIPELINE!$X8=0,"Paid",IF(DATA_PIPELINE!$W8=0,"Unpaid","Partly Paid")) -> Unpaid
A9: 4 | B9: GORORO HARROED | C9: COBEAN STATES | D9: DANMORE MUDAVANHU | E9: 63-202346-B-25 | F9: 773040703 | G9: CHEGUTU | H9: MASHWEST | I9: 29 | J9: EXISTING | K9: 0 | L9: 0 | M9: 30 | N9: 30 | O9: 6008.43 | P9: 0 | Q9: 0 | R9: 6008.43 | S9: - | T9: 30 | U9: Category A | V9: 500 | W9: =DATA_PIPELINE!$K9 -> 0 | X9: =DATA_PIPELINE!$V9-DATA_PIPELINE!$W9 -> 500 | Y9: =IF(DATA_PIPELINE!$X9=0,"Paid",IF(DATA_PIPELINE!$W9=0,"Unpaid","Partly Paid")) -> Unpaid
A10: 5 | B10: MATHUTHU FUNNY | C10: COBEAN ESTATE | D10: DANMORE MUDAVANHU | E10: 29-075854-N-21 | F10: 712521593 | G10: CHEGUTU | H10: MASHWEST | I10: 29 | J10: EXISTING | K10: 0 | L10: 0 | M10: 20 | N10: 20 | O10: 4415.12 | P10: 0 | Q10: 0 | R10: 4415.12 | S10: - | T10: 20 | U10: Category A | V10: 500 | W10: =DATA_PIPELINE!$K10 -> 0 | X10: =DATA_PIPELINE!$V10-DATA_PIPELINE!$W10 -> 500 | Y10: =IF(DATA_PIPELINE!$X10=0,"Paid",IF(DATA_PIPELINE!$W10=0,"Unpaid","Partly Paid")) -> Unpaid
A11: 6 | B11: MKWENA CAUL | C11: 43 COBEAN ESTATE | D11: DANMORE MUDAVANHU | E11: 70-2000429-T-04 | F11: 785980422 | G11: CHEGUTU | H11: MASHEAST | I11: 29 | J11: EXISTING | K11: 0 | L11: 0 | M11: 20 | N11: 20 | O11: 4415.12 | P11: 0 | Q11: 0 | R11: 4415.12 | S11: - | T11: 20 | U11: Category A | V11: 500 | W11: =DATA_PIPELINE!$K11 -> 0 | X11: =DATA_PIPELINE!$V11-DATA_PIPELINE!$W11 -> 500 | Y11: =IF(DATA_PIPELINE!$X11=0,"Paid",IF(DATA_PIPELINE!$W11=0,"Unpaid","Partly Paid")) -> Unpaid
A12: 7 | B12: JANDELES VALERIE | C12: CHIKAGO FARM | D12: DANMORE MUDAVANHU | E12: 63-708750-Q-00 | F12: 772216457 | G12: CHEGUTU | H12: MASHWEST | I12: 29 | J12: EXISTING | K12: 0 | L12: 0 | M12: 25 | N12: 25 | O12: 5316.94 | P12: 0 | Q12: 0 | R12: 5316.94 | S12: - | T12: 25 | U12: Category A | V12: 500 | W12: =DATA_PIPELINE!$K12 -> 0 | X12: =DATA_PIPELINE!$V12-DATA_PIPELINE!$W12 -> 500 | Y12: =IF(DATA_PIPELINE!$X12=0,"Paid",IF(DATA_PIPELINE!$W12=0,"Unpaid","Partly Paid")) -> Unpaid
A13: 8 | B13: MOYO CHARLES | C13: 25 COBEAN ESTATE | D13: DANMORE MUDAVANHU | E13: 29-062067-C-21 | F13: 718363313 | G13: CHEGUTU | H13: MASHWEST | I13: 29 | J13: EXISTING | K13: 0 | L13: 0 | M13: 20 | N13: 20 | O13: 4415.12 | P13: 0 | Q13: 0 | R13: 4415.12 | S13: - | T13: 20 | U13: Category A | V13: 500 | W13: =DATA_PIPELINE!$K13 -> 0 | X13: =DATA_PIPELINE!$V13-DATA_PIPELINE!$W13 -> 500 | Y13: =IF(DATA_PIPELINE!$X13=0,"Paid",IF(DATA_PIPELINE!$W13=0,"Unpaid","Partly Paid")) -> Unpaid
A14: 9 | B14: CHIKOMWE SHINE | C14: FAUN FARM PLOT 1 | D14: DANMORE MUDAVANHU | E14: 38-047571-E-38 | F14: 712730426 | G14: CHEGUTU | H14: MASHWEST | J14: EXISTING | K14: 0 | L14: 0 | M14: 80 | N14: 80 | O14: 12654.97 | P14: 0 | Q14: 0 | R14: 12654.97 | S14: - | T14: 80 | U14: Category A | V14: 500 | W14: =DATA_PIPELINE!$K14 -> 0 | X14: =DATA_PIPELINE!$V14-DATA_PIPELINE!$W14 -> 500 | Y14: =IF(DATA_PIPELINE!$X14=0,"Paid",IF(DATA_PIPELINE!$W14=0,"Unpaid","Partly Paid")) -> Unpaid
A15: 10 | B15: MUDAVANHU D | C15: MUDAVANHU FARM CHEGUTU | D15: DANMORE MUDAVANHU | E15: 27-165809-C-03 | F15: 772960915 | G15: CHEGUTU | H15: MASHWEST | J15: EXISTING | K15: 0 | L15: 0 | M15: 100 | N15: 100 | O15: 27964.77 | P15: 0 | Q15: 0 | R15: 27964.77 | S15: - | T15: 100 | U15: Category A | V15: 500 | W15: =DATA_PIPELINE!$K15 -> 0 | X15: =DATA_PIPELINE!$V15-DATA_PIPELINE!$W15 -> 500 | Y15: =IF(DATA_PIPELINE!$X15=0,"Paid",IF(DATA_PIPELINE!$W15=0,"Unpaid","Partly Paid")) -> Unpaid
A16: 11 | B16: GORA DOCAS | C16: PLOT 4 JAMAICA FARM | D16: DANMORE MUDAVANHU | E16: 32-188882-P-26 | F16: 773409156 | G16: CHEGUTU | H16: MASHWEST | J16: EXISTING | K16: 0 | L16: 0 | M16: 15 | N16: 15 | O16: 2807.94 | P16: 0 | Q16: 0 | R16: 2807.94 | S16: - | T16: 15 | U16: Category A | V16: 500 | W16: =DATA_PIPELINE!$K16 -> 0 | X16: =DATA_PIPELINE!$V16-DATA_PIPELINE!$W16 -> 500 | Y16: =IF(DATA_PIPELINE!$X16=0,"Paid",IF(DATA_PIPELINE!$W16=0,"Unpaid","Partly Paid")) -> Unpaid
A17: 12 | B17: MAVUNGA COMBOSI S | C17: HIPPOVALE FARM PLOT 5 | D17: DANMORE MUDAVANHU | E17: 08-285801-E-32 | F17: 715082150 | G17: CHEGUTU | H17: MASHWEST | J17: EXISTING | K17: 0 | L17: 0 | M17: 10 | N17: 10 | O17: 4433.03 | P17: 0 | Q17: 0 | R17: 4433.03 | S17: - | T17: 10 | U17: Category A | V17: 500 | W17: =DATA_PIPELINE!$K17 -> 0 | X17: =DATA_PIPELINE!$V17-DATA_PIPELINE!$W17 -> 500 | Y17: =IF(DATA_PIPELINE!$X17=0,"Paid",IF(DATA_PIPELINE!$W17=0,"Unpaid","Partly Paid")) -> Unpaid
A18: 13 | B18: MWAMLOWE OLIVIA | C18: 2 AQUARUS FARM GADZEMA | D18: DANMORE MUDAVANHU | E18: 24066249-Q-85 | F18: 772407927 | G18: CHEGUTU | H18: MASHWEST | J18: EXISTING | K18: 0 | L18: 0 | M18: 20 | N18: 20 | O18: 4743.76 | P18: 0 | Q18: 0 | R18: 4743.76 | S18: - | T18: 20 | U18: Category A | V18: 500 | W18: =DATA_PIPELINE!$K18 -> 0 | X18: =DATA_PIPELINE!$V18-DATA_PIPELINE!$W18 -> 500 | Y18: =IF(DATA_PIPELINE!$X18=0,"Paid",IF(DATA_PIPELINE!$W18=0,"Unpaid","Partly Paid")) -> Unpaid
A19: 14 | B19: KADZOMBE TRUST | C19: THE GROOVE FARM 1 | D19: DANMORE MUDAVANHU | E19: 32-123646-F-71 | F19: 783308067 | G19: CHEGUTU | H19: MASHWEST | J19: EXISTING | K19: 0 | L19: 0 | M19: 10 | N19: 10 | O19: 273 | P19: 0 | Q19: 0 | R19: 273 | S19: - | T19: 10 | U19: Category A | V19: 500 | W19: =DATA_PIPELINE!$K19 -> 0 | X19: =DATA_PIPELINE!$V19-DATA_PIPELINE!$W19 -> 500 | Y19: =IF(DATA_PIPELINE!$X19=0,"Paid",IF(DATA_PIPELINE!$W19=0,"Unpaid","Partly Paid")) -> Unpaid
A20: 15 | B20: MUBWANDARIKWA K | C20: COBUN ESTATE | D20: DANMORE MUDAVANHU | E20: 18-064080-T-27 | F20: 772590002 | G20: CHEGUTU | H20: MASHWEST | J20: EXISTING | K20: 0 | L20: 0 | M20: 30 | N20: 30 | O20: 7215.09 | P20: 0 | Q20: 0 | R20: 7215.09 | S20: - | T20: 30 | U20: Category A | V20: 500 | W20: =DATA_PIPELINE!$K20 -> 0 | X20: =DATA_PIPELINE!$V20-DATA_PIPELINE!$W20 -> 500 | Y20: =IF(DATA_PIPELINE!$X20=0,"Paid",IF(DATA_PIPELINE!$W20=0,"Unpaid","Partly Paid")) -> Unpaid
A21: 16 | B21: CHIWERA BLESSING | C21: ITAFA FARM , CTC | D21: DANMORE MUDAVANHU | E21: 18-088449-G-18 | F21: 772714503 | G21: KADOMA | H21: MASHWEST | I21: 4 | J21: EXISTING | K21: 0 | L21: 0 | M21: 60 | N21: 80 | O21: 20224.72 | P21: 0 | Q21: 0 | R21: 20224.72 | S21: - | T21: 80 | U21: Category A | V21: 500 | W21: =DATA_PIPELINE!$K21 -> 0 | X21: =DATA_PIPELINE!$V21-DATA_PIPELINE!$W21 -> 500 | Y21: =IF(DATA_PIPELINE!$X21=0,"Paid",IF(DATA_PIPELINE!$W21=0,"Unpaid","Partly Paid")) -> Unpaid
A22: 17 | B22: MACHIYA TAKUNDA | C22: PLOT 14 RAILWAY FARM | D22: DANMORE MUDAVANHU | E22: 24-181927-C22 | F22: 771525189 | G22: KADOMA | H22: MASHWEST | J22: EXISTING | K22: 0 | L22: 0 | M22: 25 | N22: 40 | O22: 6639.56 | P22: 0 | Q22: 0 | R22: 6639.56 | S22: - | T22: 40 | U22: Category A | V22: 500 | W22: =DATA_PIPELINE!$K22 -> 0 | X22: =DATA_PIPELINE!$V22-DATA_PIPELINE!$W22 -> 500 | Y22: =IF(DATA_PIPELINE!$X22=0,"Paid",IF(DATA_PIPELINE!$W22=0,"Unpaid","Partly Paid")) -> Unpaid
A23: 18 | B23: JAMELA BEATRICE | C23: COMBE FARM KADOMA | D23: DANMORE MUDAVANHU | E23: 24-097588-E-24 | F23: 772207146 | G23: KADOMA | H23: MASHWEST | J23: EXISTING | K23: 0 | L23: 0 | M23: 50 | N23: 50 | O23: 9777.72 | P23: 0 | Q23: 0 | R23: 9777.72 | S23: - | T23: 50 | U23: Category A | V23: 500 | W23: =DATA_PIPELINE!$K23 -> 0 | X23: =DATA_PIPELINE!$V23-DATA_PIPELINE!$W23 -> 500 | Y23: =IF(DATA_PIPELINE!$X23=0,"Paid",IF(DATA_PIPELINE!$W23=0,"Unpaid","Partly Paid")) -> Unpaid
A24: 19 | B24: KADOMA PRISSONS | C24: KADOMA PRISON FARM | D24: DANMORE MUDAVANHU | E24: 32-065804-J-26 | F24: 774383463 | G24: KADOMA | H24: MASHWEST | J24: EXISTING | K24: 0 | L24: 0 | M24: 20 | N24: 40 | O24: 2555.28 | P24: 0 | Q24: 0 | R24: 2555.28 | S24: - | T24: 40 | U24: Category A | V24: 500 | W24: =DATA_PIPELINE!$K24 -> 0 | X24: =DATA_PIPELINE!$V24-DATA_PIPELINE!$W24 -> 500 | Y24: =IF(DATA_PIPELINE!$X24=0,"Paid",IF(DATA_PIPELINE!$W24=0,"Unpaid","Partly Paid")) -> Unpaid
A25: 20 | B25: MARECHA MICHIEL | C25: NK | D25: DANMORE MUDAVANHU | E25: 22-026458-Z-04 | F25: 760572096 | G25: CHEGUTU | H25: MASHWEST | J25: EXISTING | K25: 0 | L25: 0 | M25: 20 | N25: 20 | O25: 2389.4 | P25: 0 | Q25: 0 | R25: 2389.4 | S25: - | T25: 20 | U25: Category A | V25: 500 | W25: =DATA_PIPELINE!$K25 -> 0 | X25: =DATA_PIPELINE!$V25-DATA_PIPELINE!$W25 -> 500 | Y25: =IF(DATA_PIPELINE!$X25=0,"Paid",IF(DATA_PIPELINE!$W25=0,"Unpaid","Partly Paid")) -> Unpaid
A26: 21 | B26: CHIMBETU COLLEN | C26: NK | D26: DANMORE MUDAVANHU | E26: 63-1138140-R-63 | G26: CHEGUTU | H26: MASHWEST | J26: EXISTING | K26: 0 | L26: 0 | M26: 25 | N26: 30 | O26: 5447.2 | P26: 0 | Q26: 0 | R26: 5447.2 | S26: - | T26: 30 | U26: Category A | V26: 500 | W26: =DATA_PIPELINE!$K26 -> 0 | X26: =DATA_PIPELINE!$V26-DATA_PIPELINE!$W26 -> 500 | Y26: =IF(DATA_PIPELINE!$X26=0,"Paid",IF(DATA_PIPELINE!$W26=0,"Unpaid","Partly Paid")) -> Unpaid
A27: 22 | B27: MASHOKO TINASHE | C27: PLOT 15 TORDAT FARM CHEGUTU | D27: DANMORE MUDAVANHU | E27: 32-191454-K-32 | F27: 777241382 | G27: CHEGUTU | H27: MASHWEST | J27: EXISTING | K27: 0 | L27: 0 | M27: 6 | N27: 20 | O27: 891.92 | P27: 0 | Q27: 0 | R27: 891.92 | S27: - | T27: 20 | U27: Category A | V27: 500 | W27: =DATA_PIPELINE!$K27 -> 0 | X27: =DATA_PIPELINE!$V27-DATA_PIPELINE!$W27 -> 500 | Y27: =IF(DATA_PIPELINE!$X27=0,"Paid",IF(DATA_PIPELINE!$W27=0,"Unpaid","Partly Paid")) -> Unpaid
A28: 23 | B28: IMPALAVALE FARM CHATIKOBO | C28: IMPALAVALE FARM | D28: DANMORE MUDAVANHU | E28: 63-900087-Q-26 | F28: 779729830 | G28: MHONDORO NGEZI | H28: MASHWEST | J28: EXISTING | K28: 0 | L28: 0 | M28: 80 | N28: 100 | O28: 11668.01 | P28: 0 | Q28: 0 | R28: 11668.01 | S28: - | T28: 100 | U28: Category A | V28: 500 | W28: =DATA_PIPELINE!$K28 -> 0 | X28: =DATA_PIPELINE!$V28-DATA_PIPELINE!$W28 -> 500 | Y28: =IF(DATA_PIPELINE!$X28=0,"Paid",IF(DATA_PIPELINE!$W28=0,"Unpaid","Partly Paid")) -> Unpaid
A29: 24 | B29: MAMINA IRRIGATION SCHEME | C29: MAMINA IRRIGATION SCHEME | D29: DANMORE MUDAVANHU | E29: 63-446623-V-24 | F29: 772354114 | G29: MHONDORO NGEZI | H29: MASHWEST | J29: EXISTING | K29: 0 | L29: 0 | M29: 145 | N29: 200 | O29: 17554.89 | P29: 0 | Q29: 0 | R29: 17554.89 | S29: - | T29: 200 | U29: Category B | V29: 1000 | W29: =DATA_PIPELINE!$K29 -> 0 | X29: =DATA_PIPELINE!$V29-DATA_PIPELINE!$W29 -> 1000 | Y29: =IF(DATA_PIPELINE!$X29=0,"Paid",IF(DATA_PIPELINE!$W29=0,"Unpaid","Partly Paid")) -> Unpaid
A30: 25 | B30: GAKA RODRICK | C30: 46 COBERN ESTATES CHEGUTU | D30: DANMORE MUDAVANHU | E30: 29-178061-H-12 | F30: 772251262 | G30: CHEGUTU | H30: MASHWEST | J30: EXISTING | K30: 0 | L30: 0 | M30: 50 | N30: 50 | O30: 8329.52 | P30: 0 | Q30: 0 | R30: 8329.52 | S30: - | T30: 50 | U30: Category A | V30: 500 | W30: =DATA_PIPELINE!$K30 -> 0 | X30: =DATA_PIPELINE!$V30-DATA_PIPELINE!$W30 -> 500 | Y30: =IF(DATA_PIPELINE!$X30=0,"Paid",IF(DATA_PIPELINE!$W30=0,"Unpaid","Partly Paid")) -> Unpaid
A31: 26 | B31: ZUNGUNDE BETTY | C31: KENT ESTATE | D31: BETTY ZUNGUNDE | E31: 32-122405-G-38 | F31: 773868322 | G31: CHEGUTU | H31: MASHWEST | I31: 14 | J31: EXISTING | K31: 50 | L31: 0 | M31: 0 | N31: 80 | O31: 18089.72 | P31: 3.04 | Q31: 1108.84 | R31: 16980.88 | S31: 6.13 | T31: 80 | U31: Category A | V31: 500 | W31: =DATA_PIPELINE!$K31 -> 50 | X31: =DATA_PIPELINE!$V31-DATA_PIPELINE!$W31 -> 450 | Y31: =IF(DATA_PIPELINE!$X31=0,"Paid",IF(DATA_PIPELINE!$W31=0,"Unpaid","Partly Paid")) -> Partly Paid
A32: 27 | B32: MARUFU DEPHINE | C32: KILWORTH FARM | D32: BETTY ZUNGUNDE | E32: 63-1541739-L-05 | F32: 774518500 | G32: CHEGUTU | H32: MASHWEST | J32: EXISTING | K32: 0 | L32: 0 | M32: 0 | N32: 40 | O32: 9236.5 | P32: 0 | Q32: 0 | R32: 9236.5 | S32: - | T32: 40 | U32: Category A | V32: 500 | W32: =DATA_PIPELINE!$K32 -> 0 | X32: =DATA_PIPELINE!$V32-DATA_PIPELINE!$W32 -> 500 | Y32: =IF(DATA_PIPELINE!$X32=0,"Paid",IF(DATA_PIPELINE!$W32=0,"Unpaid","Partly Paid")) -> Unpaid
A33: 28 | B33: MUTSVANGWA MONICA | C33: NK | D33: BETTY ZUNGUNDE | E33: 63-438218-B-70* | G33: CHEGUTU | H33: MASHWEST | J33: EXISTING | K33: 0 | L33: 0 | M33: 0 | N33: 40 | O33: 546 | P33: 0 | Q33: 0 | R33: 546 | S33: - | T33: 40 | U33: Category A | V33: 500 | W33: =DATA_PIPELINE!$K33 -> 0 | X33: =DATA_PIPELINE!$V33-DATA_PIPELINE!$W33 -> 500 | Y33: =IF(DATA_PIPELINE!$X33=0,"Paid",IF(DATA_PIPELINE!$W33=0,"Unpaid","Partly Paid")) -> Unpaid
A34: 29 | B34: NYENYAI ANGELINE | C34: NK | D34: BETTY ZUNGUNDE | E34: 70-459721-B-70* | G34: CHEGUTU | H34: MASHWEST | J34: EXISTING | K34: 0 | L34: 0 | M34: 0 | N34: 60 | O34: 11580.73 | P34: 0 | Q34: 0 | R34: 11580.73 | S34: - | T34: 60 | U34: Category A | V34: 500 | W34: =DATA_PIPELINE!$K34 -> 0 | X34: =DATA_PIPELINE!$V34-DATA_PIPELINE!$W34 -> 500 | Y34: =IF(DATA_PIPELINE!$X34=0,"Paid",IF(DATA_PIPELINE!$W34=0,"Unpaid","Partly Paid")) -> Unpaid
A35: 30 | B35: MUTSVANGWA MONICA | C35: MONCHRIS FARM | D35: BETTY ZUNGUNDE | E35: 63-905294-A-32 | F35: 772572470 | G35: CHEGUTU | H35: MASHWEST | J35: EXISTING | K35: 0 | L35: 0 | M35: 0 | N35: 0 | O35: 844.01 | P35: 0 | Q35: 0 | R35: 844.01 | S35: - | T35: 0 | U35: Category A | V35: 500 | W35: =DATA_PIPELINE!$K35 -> 0 | X35: =DATA_PIPELINE!$V35-DATA_PIPELINE!$W35 -> 500 | Y35: =IF(DATA_PIPELINE!$X35=0,"Paid",IF(DATA_PIPELINE!$W35=0,"Unpaid","Partly Paid")) -> Unpaid
A36: 31 | B36: MUTIWASEKWA ITAI | C36: PLOT 3 HUNYANI ETSTATE NORTON | D36: BETTY ZUNGUNDE | E36: 32088464-P-44 | F36: 715111991 | G36: CHEGUTU | H36: MASHWEST | J36: EXISTING | K36: 0 | L36: 0 | M36: 0 | N36: 40 | O36: 11005.69 | P36: 0 | Q36: 0 | R36: 11005.69 | S36: - | T36: 40 | U36: Category A | V36: 500 | W36: =DATA_PIPELINE!$K36 -> 0 | X36: =DATA_PIPELINE!$V36-DATA_PIPELINE!$W36 -> 500 | Y36: =IF(DATA_PIPELINE!$X36=0,"Paid",IF(DATA_PIPELINE!$W36=0,"Unpaid","Partly Paid")) -> Unpaid
A37: 32 | B37: MUJURU D | C37: SIVUNDAZI FAM | D37: BETTY ZUNGUNDE | E37: 63-948959-M-80 | F37: 718840612 | G37: CHEGUTU | H37: MASHWEST | I37: 26 | J37: EXISTING | K37: 0 | L37: 0 | M37: 0 | N37: 180 | O37: 27779.25 | P37: 0 | Q37: 0 | R37: 27779.25 | S37: - | T37: 180 | U37: Category A | V37: 500 | W37: =DATA_PIPELINE!$K37 -> 0 | X37: =DATA_PIPELINE!$V37-DATA_PIPELINE!$W37 -> 500 | Y37: =IF(DATA_PIPELINE!$X37=0,"Paid",IF(DATA_PIPELINE!$W37=0,"Unpaid","Partly Paid")) -> Unpaid
A38: 33 | B38: MANYAWU E.T | C38: DAIZY FARM | D38: BETTY ZUNGUNDE | E38: 63-817650-K-50 | F38: 773447211 | G38: CHEGUTU | H38: MASHWEST | I38: 15 | J38: EXISTING | K38: 0 | L38: 0 | M38: 0 | N38: 25 | O38: 4565.02 | P38: 0 | Q38: 0 | R38: 4565.02 | S38: - | T38: 25 | U38: Category A | V38: 500 | W38: =DATA_PIPELINE!$K38 -> 0 | X38: =DATA_PIPELINE!$V38-DATA_PIPELINE!$W38 -> 500 | Y38: =IF(DATA_PIPELINE!$X38=0,"Paid",IF(DATA_PIPELINE!$W38=0,"Unpaid","Partly Paid")) -> Unpaid
A39: 34 | B39: MUSWEHAURARI CHIPO | C39: BURNBANK FARM | D39: BETTY ZUNGUNDE | E39: 42-144968-X-42 | F39: 772816696 | G39: CHEGUTU | H39: MASHWEST | I39: 28 | J39: EXISTING | K39: 0 | L39: 0 | M39: 10 | N39: 50 | O39: 8300.95 | P39: 4.05 | Q39: 1477.24 | R39: 6823.71 | S39: 17.8 | T39: 60 | U39: Category A | V39: 500 | W39: =DATA_PIPELINE!$K39 -> 0 | X39: =DATA_PIPELINE!$V39-DATA_PIPELINE!$W39 -> 500 | Y39: =IF(DATA_PIPELINE!$X39=0,"Paid",IF(DATA_PIPELINE!$W39=0,"Unpaid","Partly Paid")) -> Unpaid
A40: 35 | B40: TAKAVADA KELVIN | C40: DAIZY FARM | D40: BETTY ZUNGUNDE | E40: 86-053962-P-22 | F40: 773084706 | G40: CHEGUTU | H40: MASHWEST | I40: 15 | J40: EXISTING | K40: 0 | L40: 0 | M40: 0 | N40: 40 | O40: 8629.59 | P40: 0 | Q40: 0 | R40: 8629.59 | S40: - | T40: 40 | U40: Category A | V40: 500 | W40: =DATA_PIPELINE!$K40 -> 0 | X40: =DATA_PIPELINE!$V40-DATA_PIPELINE!$W40 -> 500 | Y40: =IF(DATA_PIPELINE!$X40=0,"Paid",IF(DATA_PIPELINE!$W40=0,"Unpaid","Partly Paid")) -> Unpaid
A41: 36 | B41: MARTINDALE FARM LCBL | C41: MARTINDALE FARM | D41: BETTY ZUNGUNDE | E41: 63-709780-K-70 | F41: 775986483 | G41: CHEGUTU | H41: MASHWEST | J41: EXISTING | K41: 0 | L41: 0 | M41: 0 | N41: 20 | O41: 2447.07 | P41: 0 | Q41: 0 | R41: 2447.07 | S41: - | T41: 20 | U41: Category A | V41: 500 | W41: =DATA_PIPELINE!$K41 -> 0 | X41: =DATA_PIPELINE!$V41-DATA_PIPELINE!$W41 -> 500 | Y41: =IF(DATA_PIPELINE!$X41=0,"Paid",IF(DATA_PIPELINE!$W41=0,"Unpaid","Partly Paid")) -> Unpaid
...

Sheet DATA_RECEIPTS
A1: DATA RECEIPTS
A2: Imported source snapshot — update this table when source workbooks change.
A3: =HYPERLINK("#'HOME'!A1","HOME") -> HOME | B3: =HYPERLINK("#'FARMERS'!A1","FARMERS") -> FARMERS | C3: =HYPERLINK("#'SUBSCRIPTIONS'!A1","SUBSCRIPTIONS") -> SUBSCRIPTIONS | D3: =HYPERLINK("#'PRODUCTION'!A1","PRODUCTION") -> PRODUCTION | E3: =HYPERLINK("#'RECOVERY'!A1","RECOVERY") -> RECOVERY | F3: =HYPERLINK("#'DELIVERIES'!A1","DELIVERIES") -> DELIVERIES | G3: =HYPERLINK("#'FINANCE'!A1","FINANCE") -> FINANCE
A5: MONTH | B5: DATE | C5: FARMER NAME | D5: AMOUNT DUE | E5: AMOUNT PAID | F5: BALANCE | G5: TYPE
A6: 45962 | B6: 45986 | C6: LENIN MUTANGARA | D6: 1000 | E6: 1000 | F6: =DATA_RECEIPTS!$D6-DATA_RECEIPTS!$E6 -> 0 | G6: Cash
A7: 45962 | B7: 45984 | C7: ISAIAH DAVISON FARAI CHAKUCHICHI | D7: 1000 | E7: 1000 | F7: =DATA_RECEIPTS!$D7-DATA_RECEIPTS!$E7 -> 0 | G7: Cash
A8: 45962 | B8: 45984 | C8: TICHAONA MAPFOCHE | D8: 1000 | E8: 1000 | F8: =DATA_RECEIPTS!$D8-DATA_RECEIPTS!$E8 -> 0 | G8: Cash
A9: 45962 | B9: 45984 | C9: FUNGAI MAKONI | D9: 1000 | E9: 1000 | F9: =DATA_RECEIPTS!$D9-DATA_RECEIPTS!$E9 -> 0 | G9: Cash
A10: 45962 | B10: 45987 | C10: MUTIBURA PHEBEON | D10: 1000 | E10: 1000 | F10: =DATA_RECEIPTS!$D10-DATA_RECEIPTS!$E10 -> 0 | G10: Cash
A11: 45962 | B11: 45987 | C11: WENDEY MADZURA | D11: 500 | E11: 500 | F11: =DATA_RECEIPTS!$D11-DATA_RECEIPTS!$E11 -> 0 | G11: Cash
A12: 45962 | B12: 45987 | C12: NHEMA TAKUNDA | D12: 1000 | E12: 1000 | F12: =DATA_RECEIPTS!$D12-DATA_RECEIPTS!$E12 -> 0 | G12: Cash
A13: 45962 | B13: 45987 | C13: MASHURA LIBERTY | D13: 1000 | E13: 1000 | F13: =DATA_RECEIPTS!$D13-DATA_RECEIPTS!$E13 -> 0 | G13: Cash
A14: 46174 | B14: 46184 | C14: ABIGAIL ZARANYIKA | D14: 500 | E14: 500 | F14: =DATA_RECEIPTS!$D14-DATA_RECEIPTS!$E14 -> 0 | G14: Cash
A15: 46174 | B15: 46198 | C15: NATSAI NHEMACHENA | D15: 500 | E15: 200 | F15: =DATA_RECEIPTS!$D15-DATA_RECEIPTS!$E15 -> 300 | G15: Cash
A16: 46204 | B16: 46206 | C16: TENDAI BARE | D16: 300 | E16: 300 | F16: =DATA_RECEIPTS!$D16-DATA_RECEIPTS!$E16 -> 0
A17: 46204 | B17: 46219 | C17: DAVISON MADHIGI | D17: 500 | E17: 500 | F17: =DATA_RECEIPTS!$D17-DATA_RECEIPTS!$E17 -> 0 | G17: Bank
A18: 46204 | B18: 46227 | C18: MALTINA MASHAVA | D18: 500 | E18: 500 | F18: =DATA_RECEIPTS!$D18-DATA_RECEIPTS!$E18 -> 0
A19: 46204 | B19: 46227 | C19: TAZVIVINGA FOROMA | D19: 500 | E19: 100 | F19: =DATA_RECEIPTS!$D19-DATA_RECEIPTS!$E19 -> 400
A20: 46204 | B20: 46227 | C20: WALTER MASHINGAIDZE | D20: 500 | E20: 200 | F20: =DATA_RECEIPTS!$D20-DATA_RECEIPTS!$E20 -> 300
A21: 46235 | B21: 46237 | C21: GURAMATUNHU OBEY | D21: 500 | E21: 200 | F21: =DATA_RECEIPTS!$D21-DATA_RECEIPTS!$E21 -> 300
A22: 46235 | B22: 46237 | C22: TAPFUMANEYI RUTH | D22: 500 | E22: 100 | F22: =DATA_RECEIPTS!$D22-DATA_RECEIPTS!$E22 -> 400 | G22: Bank
A23: 46235 | B23: 46237 | C23: CHAFAUSIPO CLIFFORD | D23: 500 | E23: 100 | F23: =DATA_RECEIPTS!$D23-DATA_RECEIPTS!$E23 -> 400 | G23: Bank
A24: 46235 | B24: 46238 | C24: MAZONDE FARAI | D24: 500 | E24: 100 | F24: =DATA_RECEIPTS!$D24-DATA_RECEIPTS!$E24 -> 400 | G24: Bank
A25: 46235 | B25: 46237 | C25: PAUCHENI MASANGO | D25: 500 | E25: 500 | F25: =DATA_RECEIPTS!$D25-DATA_RECEIPTS!$E25 -> 0 | G25: Bank
A26: 46235 | B26: 46237 | C26: MAMBO MUSONA | D26: 500 | E26: 200 | F26: =DATA_RECEIPTS!$D26-DATA_RECEIPTS!$E26 -> 300 | G26: Bank
A27: 46235 | B27: 46240 | C27: DORREEN NYARADZAI | D27: 500 | E27: 100 | F27: =DATA_RECEIPTS!$D27-DATA_RECEIPTS!$E27 -> 400 | G27: Bank
A28: 46246 | B28: 46241 | C28: PATIENCE MUTANGADURA | D28: 500 | E28: 500 | F28: =DATA_RECEIPTS!$D28-DATA_RECEIPTS!$E28 -> 0 | G28: Bank
A29: 46235 | B29: 46243 | C29: TSORAI EDNA | D29: 500 | E29: 100 | F29: =DATA_RECEIPTS!$D29-DATA_RECEIPTS!$E29 -> 400 | G29: Bank
A30: 46260 | B30: 46246 | C30: MASHAVAVE SIMBARASHE | D30: 500 | E30: 100 | F30: =DATA_RECEIPTS!$D30-DATA_RECEIPTS!$E30 -> 400 | G30: bank
A31: 46248 | B31: 46248 | C31: NYACHOWE LEO | D31: 500 | E31: 100 | F31: =DATA_RECEIPTS!$D31-DATA_RECEIPTS!$E31 -> 400 | G31: Bank
A32: 46248 | B32: 46248 | C32: ZUNGUNDE BETTY | D32: 500 | E32: 50 | F32: =DATA_RECEIPTS!$D32-DATA_RECEIPTS!$E32 -> 450 | G32: Bank
A33: 46248 | B33: 46248 | C33: RETIWA REGIS | D33: 500 | E33: 200 | F33: =DATA_RECEIPTS!$D33-DATA_RECEIPTS!$E33 -> 300 | G33: Bank
A34: 46251 | B34: 46251 | C34: MATIYENGA MUNYARADZI | D34: 500 | E34: 100 | F34: =DATA_RECEIPTS!$D34-DATA_RECEIPTS!$E34 -> 400 | G34: Bank
A35: 46252 | B35: 46252 | C35: MELLODY N CHITIYO | D35: 500 | E35: 100 | F35: 400 | G35: Bank
A36: 46255 | B36: 46255 | C36: GAMUCHIRAI CHIDARIKIRE | D36: 500 | E36: 200 | F36: =DATA_RECEIPTS!$D36-DATA_RECEIPTS!$E36 -> 300 | G36: Bank
A37: 46255 | B37: 46255 | C37: PETER MATARUSE | D37: 500 | E37: 200 | F37: 200 | G37: Bank
A38: 46258 | B38: 46258 | C38: MUTARA COMMENT | D38: 500 | E38: 100 | F38: =DATA_RECEIPTS!$D38-DATA_RECEIPTS!$E38 -> 400 | G38: Bank
A39: 46254 | B39: 46254 | C39: CLIVE CHOTO | D39: 500 | E39: 100 | F39: =DATA_RECEIPTS!$D39-DATA_RECEIPTS!$E39 -> 400 | G39: Bank
A40: 46258 | B40: 46258 | C40: FUNNY MUNYONGA | D40: 500 | E40: 50 | F40: =DATA_RECEIPTS!$D40-DATA_RECEIPTS!$E40 -> 450 | G40: Bank
A41: 46259 | B41: 46259 | C41: ERNERST KAPUYA | D41: 500 | E41: 250 | F41: =DATA_RECEIPTS!$D41-DATA_RECEIPTS!$E41 -> 250 | G41: Bank
...

Sheet SGR ASSET REGISTER
A1: SGR ASSET REGISTER & DEPRECIATION SCHEDULE
A2: Fixed asset register with straight-line depreciation, accumulated depreciation and closing net book value.
A4: =HYPERLINK("#'HOME'!A1","HOME") -> HOME | B4: =HYPERLINK("#'FINANCE'!A1","FINANCE") -> FINANCE | C4: =HYPERLINK("#'REPORTS'!A1","REPORTS") -> REPORTS | D4: =HYPERLINK("#'PRODUCTION'!A1","PRODUCTION") -> PRODUCTION | E4: =HYPERLINK("#'SORGHUM BUDGET'!A1","SORGHUM BUDGET") -> SORGHUM BUDGET | F4: =HYPERLINK("#'MAIZE BUDGET'!A1","MAIZE BUDGET") -> MAIZE BUDGET
A6: Asset ID | B6: Asset Description | C6: Category | D6: Purchase Date | E6: Cost (USD) | F6: Residual Value (USD) | G6: Useful Life (Years) | H6: Annual Depreciation (USD) | I6: Accumulated Depreciation (USD) | J6: Closing NBV (USD)
A7: COM1 | B7: HP-ELITEBOOK 840 CORE i7 | C7: Laptop | D7: 46265 | E7: 390 | F7: 80 | G7: 2 | H7: =IF(OR(E7="",F7="",G7=""),"",MAX(0,(E7-F7)/G7)) -> 155 | I7: =IF(OR(H7="",D7=""),"",MIN(E7-F7,H7*MAX(0,YEARFRAC(D7,DATE(2027,8,31))))) -> 155 | J7: =IF(E7="","",MAX(F7,E7-IF(I7="",0,I7))) -> 235
A8: CH01 | B8: MESH VISITORS CHAIRS | C8: Office Equipment | D8: 46265 | E8: 380 | F8: 16 | G8: 1 | H8: =IF(OR(E8="",F8="",G8=""),"",MAX(0,(E8-F8)/G8)) -> 364 | I8: =IF(OR(H8="",D8=""),"",MIN(E8-F8,H8*MAX(0,YEARFRAC(D8,DATE(2027,8,31))))) -> 364 | J8: =IF(E8="","",MAX(F8,E8-IF(I8="",0,I8))) -> 16
H9: =IF(OR(E9="",F9="",G9=""),"",MAX(0,(E9-F9)/G9)) | I9: =IF(OR(H9="",D9=""),"",MIN(E9-F9,H9*MAX(0,YEARFRAC(D9,DATE(2027,8,31))))) | J9: =IF(E9="","",MAX(F9,E9-IF(I9="",0,I9)))
H10: =IF(OR(E10="",F10="",G10=""),"",MAX(0,(E10-F10)/G10)) | I10: =IF(OR(H10="",D10=""),"",MIN(E10-F10,H10*MAX(0,YEARFRAC(D10,DATE(2027,8,31))))) | J10: =IF(E10="","",MAX(F10,E10-IF(I10="",0,I10)))
H11: =IF(OR(E11="",F11="",G11=""),"",MAX(0,(E11-F11)/G11)) | I11: =IF(OR(H11="",D11=""),"",MIN(E11-F11,H11*MAX(0,YEARFRAC(D11,DATE(2027,8,31))))) | J11: =IF(E11="","",MAX(F11,E11-IF(I11="",0,I11)))
H12: =IF(OR(E12="",F12="",G12=""),"",MAX(0,(E12-F12)/G12)) | I12: =IF(OR(H12="",D12=""),"",MIN(E12-F12,H12*MAX(0,YEARFRAC(D12,DATE(2027,8,31))))) | J12: =IF(E12="","",MAX(F12,E12-IF(I12="",0,I12)))
H13: =IF(OR(E13="",F13="",G13=""),"",MAX(0,(E13-F13)/G13)) | I13: =IF(OR(H13="",D13=""),"",MIN(E13-F13,H13*MAX(0,YEARFRAC(D13,DATE(2027,8,31))))) | J13: =IF(E13="","",MAX(F13,E13-IF(I13="",0,I13)))
H14: =IF(OR(E14="",F14="",G14=""),"",MAX(0,(E14-F14)/G14)) | I14: =IF(OR(H14="",D14=""),"",MIN(E14-F14,H14*MAX(0,YEARFRAC(D14,DATE(2027,8,31))))) | J14: =IF(E14="","",MAX(F14,E14-IF(I14="",0,I14)))
H15: =IF(OR(E15="",F15="",G15=""),"",MAX(0,(E15-F15)/G15)) | I15: =IF(OR(H15="",D15=""),"",MIN(E15-F15,H15*MAX(0,YEARFRAC(D15,DATE(2027,8,31))))) | J15: =IF(E15="","",MAX(F15,E15-IF(I15="",0,I15)))
H16: =IF(OR(E16="",F16="",G16=""),"",MAX(0,(E16-F16)/G16)) | I16: =IF(OR(H16="",D16=""),"",MIN(E16-F16,H16*MAX(0,YEARFRAC(D16,DATE(2027,8,31))))) | J16: =IF(E16="","",MAX(F16,E16-IF(I16="",0,I16)))
H17: =IF(OR(E17="",F17="",G17=""),"",MAX(0,(E17-F17)/G17)) | I17: =IF(OR(H17="",D17=""),"",MIN(E17-F17,H17*MAX(0,YEARFRAC(D17,DATE(2027,8,31))))) | J17: =IF(E17="","",MAX(F17,E17-IF(I17="",0,I17)))
H18: =IF(OR(E18="",F18="",G18=""),"",MAX(0,(E18-F18)/G18)) | I18: =IF(OR(H18="",D18=""),"",MIN(E18-F18,H18*MAX(0,YEARFRAC(D18,DATE(2027,8,31))))) | J18: =IF(E18="","",MAX(F18,E18-IF(I18="",0,I18)))
H19: =IF(OR(E19="",F19="",G19=""),"",MAX(0,(E19-F19)/G19)) | I19: =IF(OR(H19="",D19=""),"",MIN(E19-F19,H19*MAX(0,YEARFRAC(D19,DATE(2027,8,31))))) | J19: =IF(E19="","",MAX(F19,E19-IF(I19="",0,I19)))
H20: =IF(OR(E20="",F20="",G20=""),"",MAX(0,(E20-F20)/G20)) | I20: =IF(OR(H20="",D20=""),"",MIN(E20-F20,H20*MAX(0,YEARFRAC(D20,DATE(2027,8,31))))) | J20: =IF(E20="","",MAX(F20,E20-IF(I20="",0,I20)))
... H26: =IF(OR(E26="",F26="",G26=""),"",MAX(0,(E26-F26)/G26)) | I26: =IF(OR(H26="",D26=""),"",MIN(E26-F26,H26*MAX(0,YEARFRAC(D26,DATE(2027,8,31))))) | J26: =IF(E26="","",MAX(F26,E26-IF(I26="",0,I26)))
B27: TOTAL ASSET REGISTER | E27: =SUM(E7:E26) -> 770 | F27: =SUM(F7:F26) -> 96 | H27: =SUM(H7:H26) -> 519 | I27: =SUM(I7:I26) -> 519 | J27: =SUM(J7:J26) -> 251
A29: Depreciation method | B29: Straight-line
A30: Depreciation period | B30: 2026/27 reporting year to 31-Aug-2027
A31: Formula | B31: (Cost − Residual Value) ÷ Useful Life

Sheet CLUSTER PIPELINE PROJECTION
A1: SGR | SUMMER 2026/27 PIPELINE PROJECTION
A2: Executive high-level view of farmer participation and hectares scheduled for 2026/27 summer season, compared with 2025/26
A3: HOME | B3: CLUSTER FARMERS | C3: PIPELINE PROJECTION | D3: DATA PIPELINE | E3: PRODUCTION | F3: SUBSCRIPTIONS | G3: RECOVERY | H3: REPORTS
A5: REGISTERED FARMERS-2025/26 | C5: 2025/26 FARMERS (UNIQUE) | E5: FARMER PIPELINE GROWTH
A6: 429 | C6: 567 | E6: =(C6-A6)/A6 -> 0.32167832
A9: SORGHUM -2025/26 SUMMER HA | C9: 2026/27 SORGHUM HA | E9: HA PIPELINE GROWTH
A10: 16492 | C10: 20526 | E10: =(C10-A10)/A10 -> 0.24460344
A12: 2025/26 MAIZE HA | C12: 2026/27 MAIZE HA | E12: HA PIPELINE GROWTH
A13: 7144 | C13: 7144 | E13: =(C13-A13)/A13 -> 0
A18: SEASON COMPARISON
A19: METRIC | B19: 2025/26 | C19: 2026/27 | D19: CHANGE | E19: CHANGE % | F19: MANAGEMENT VIEW
A20: Farmers | B20: 429 | C20: =C6 -> 567 | D20: =C20-B20 -> 138 | E20: =E6 -> 0.32167832 | F20: More farmers scheduled
A21: Total hectares | B21: 16492 | C21: 27670 | D21: 11178 | E21: 0.678 | F21: Larger production pipeline
A22: Maize hectares | B22: 0 | C22: 7144 | D22: 7144 | F22: New maize component
A23: Sorghum hectares | B23: 16492 | C23: 20526 | D23: 4034 | E23: 0.245 | F23: Sorghum remains core crop
A25: 2026/27 TARGET CHECK
A26: CROP | B26: TARGET HA | C26: SCHEDULED HA | D26: GAP/(SURPLUS) | E26: ACHIEVEMENT | F26: STATUS
A27: MAIZE | B27: 20000 | C27: 7144 | D27: 12856 | E27: 0.357 | F27: GAP TO CLOSE
A28: SORGHUM | B28: 20000 | C28: 20526 | D28: -526 | E28: 1.026 | F28: ON / ABOVE TARGET
A29: COMBINED | B29: 40000 | C29: 27670 | D29: 12330 | E29: 0.692 | F29: GAP TO CLOSE
A32: CLUSTER PIPELINE PROJECTION
A33: CLUSTER | B33: REGISTERED-2026/27 | C33: 2025/26 FARMERS | D33: 26/27 FARMERS | E33: MAIZE HA-2025/26 | F33: MAIZE HA-2026/27 | G33: SORGHUM -2025/26 HA | H33: SORGHUM HA-2026/27 | I33: 26/27 TOTAL HA | J33: SHARE OF 26/27 HA
A34: UNKNOWN | B34: 282 | C34: 190 | D34: 236 | E34: 0 | F34: 6591 | G34: 7460 | H34: 8287 | I34: 14878 | J34: 0.538
A35: TAKUNDA NHEMA | B35: 13 | C35: 12 | D35: 12 | E35: 0 | F35: 0 | G35: 1305 | H35: 1895 | I35: 1895 | J35: 0.068 | K35: MOLEEN TO SENT
A36: MOFFAT SEFU | B36: 49 | C36: 32 | D36: 37 | E36: 0 | F36: 56 | G36: 1110 | H36: 1575 | I36: 1631 | J36: 0.059
A37: PHIBEON MUTIBURA | B37: 18 | C37: 18 | D37: 18 | E37: 0 | F37: 0 | G37: 825 | H37: 1470 | I37: 1470 | J37: 0.053
A38: BATSIRAYI MAGAYA | B38: 43 | C38: 43 | D38: 41 | E38: 0 | F38: 300 | G38: 1000 | H38: 1050 | I38: 1350 | J38: 0.049
A39: RICHARD JENAMI | B39: 26 | C39: 25 | D39: 23 | E39: 0 | F39: 0 | G39: 985 | H39: 1265 | I39: 1265 | J39: 0.046
A40: DANMORE MUDAVANHU | B40: 25 | C40: 25 | D40: 25 | E40: 0 | F40: 0 | G40: 986 | H40: 1150 | I40: 1150 | J40: 0.042 | K40: MOLLEN SHOKO
A41: COMMENT TONDERAYI MUTARA | B41: 14 | C41: 13 | D41: 12 | E41: 0 | F41: 7 | G41: 920 | H41: 1140 | I41: 1147 | J41: 0.041
A42: BRIAN CHIDAVAENZI | B42: 16 | C42: 13 | D42: 16 | E42: 0 | F42: 0 | G42: 462 | H42: 1050 | I42: 1050 | J42: 0.038
A43: UNASSIGNED / NO CLUSTER | B43: 21 | C43: 19 | D43: 20 | E43: 0 | F43: 120 | G43: 473 | H43: 544 | I43: 664 | J43: 0.024
A44: BETTY ZUNGUNDE | B44: 11 | C44: 11 | D44: 10 | E44: 0 | F44: 10 | G44: 452 | H44: 575 | I44: 585 | J44: 0.021
A45: TINASHE CHIKONDOWA | B45: 26 | C45: 23 | D45: 25 | E45: 0 | F45: 0 | G45: 369 | H45: 335 | I45: 335 | J45: 0.012
A46: WALTER MASHINGAIDZE | B46: 5 | C46: 2 | D46: 3 | E46: 0 | F46: 20 | G46: 35 | H46: 90 | I46: 110 | J46: 0.004
A47: MICHEK PARADZANWA | B47: 7 | C47: 1 | D47: 1 | E47: 0 | F47: 40 | G47: 10 | H47: 20 | I47: 60 | J47: 0.002
A48: THEMBEKILE GATA | B48: 1 | C48: 0 | D48: 1 | E48: 0 | F48: 0 | G48: 0 | H48: 50 | I48: 50 | J48: 0.002
A49: NL | B49: 1 | C49: 0 | D49: 1 | E49: 0 | F49: 0 | G49: 0 | H49: 30 | I49: 30 | J49: 0.001
A50: JAMES MASANGO | B50: 1 | C50: 1 | D50: 0 | E50: 0 | F50: 0 | G50: 100 | H50: 0 | I50: 0 | J50: 0
A51: BLESSING CHIWERA | B51: 7 | C51: 0 | D51: 0 | E51: 0 | F51: 0 | G51: 0 | H51: 0 | I51: 0 | J51: 0
...

Sheet SUBSCRIPTIONS
A1: FARMER SUBSCRIPTION DASHBOARD
A2: Subscription collections, category analysis and monthly performance
A3: =HYPERLINK("#'HOME'!A1","HOME") -> HOME | B3: =HYPERLINK("#'FARMERS'!A1","FARMERS") -> FARMERS | C3: =HYPERLINK("#'SUBSCRIPTIONS'!A1","SUBSCRIPTIONS") -> SUBSCRIPTIONS | D3: =HYPERLINK("#'PRODUCTION'!A1","PRODUCTION") -> PRODUCTION | E3: =HYPERLINK("#'RECOVERY'!A1","RECOVERY") -> RECOVERY | F3: =HYPERLINK("#'DELIVERIES'!A1","DELIVERIES") -> DELIVERIES | G3: =HYPERLINK("#'FINANCE'!A1","FINANCE") -> FINANCE | H3: =HYPERLINK("#'REPORTS'!A1","REPORTS") -> REPORTS
A5: TOTAL REGISTERED | C5: CATEGORY A (<200 HA) | E5: CATEGORY B (>=200 HA) | G5: EXPECTED INCOME | I5: INCOME RECEIVED | K5: OUTSTANDING
A6: =COUNTA(DATA_PIPELINE!$B$6:$B$601) -> 573 | C6: =COUNTIF(DATA_PIPELINE!$U$6:$U$601,"Category A") -> 515 | E6: =COUNTIF(DATA_PIPELINE!$U$6:$U$601,"Category B") -> 24 | G6: =SUM(DATA_PIPELINE!$V$6:$V$601) -> 597000 | I6: =SUM(DATA_RECEIPTS!$E$6:$E$75) -> 17375 | K6: =SUM(DATA_RECEIPTS!$F$6:$F$75) -> 14025
A9: Category | B9: Farmers | C9: Expected Income | D9: Rate | E9: Paid | I9: Hac Size | J9: Sorgum Hac | K9: Maize Ha | L9: % Contribution
A10: Category A | B10: =COUNTIF(DATA_PIPELINE!$U$6:$U$601,"Category A") -> 515 | C10: =B10*500 -> 257500 | D10: 500 | E10: 23 | I10: =SUMIFS(DATA_PIPELINE!$N$6:$N$601, DATA_PIPELINE!$U$6:$U$601, "Category A") + SUMIFS(DATA_PIPELINE!$M$6:$M$601, DATA_PIPELINE!$U$6:$U$601, "Category A") -> 19791 | J10: =SUMIFS(DATA_PIPELINE!$N$6:$N$601, DATA_PIPELINE!$U$6:$U$601, "Category A") -> 14556 | K10: =SUMIFS(DATA_PIPELINE!$M$6:$M$601, DATA_PIPELINE!$U$6:$U$601, "Category A") -> 5235 | L10: =I10/I12 -> 0.64098329
A11: Category B | B11: =COUNTIF(DATA_PIPELINE!$U$6:$U$601,"Category B") -> 24 | C11: =B11*1000 -> 24000 | D11: 1000 | E11: 7 | I11: =SUMIFS(DATA_PIPELINE!$N$6:$N$601, DATA_PIPELINE!$U$6:$U$601, "Category B") + SUMIFS(DATA_PIPELINE!$M$6:$M$601, DATA_PIPELINE!$U$6:$U$601, "Category B") -> 11085 | J11: =SUMIFS(DATA_PIPELINE!$N$6:$N$601, DATA_PIPELINE!$U$6:$U$601, "Category B") -> 5900 | K11: =SUMIFS(DATA_PIPELINE!$M$6:$M$601, DATA_PIPELINE!$U$6:$U$601, "Category B") -> 5185 | L11: =I11/I12 -> 0.35901671
H12: Total | I12: =I10+I11 -> 30876 | J12: =J10+J11 -> 20456 | K12: =K10+K11 -> 10420 | L12: =L10+L11 -> 1
A14: Monthly collections
A15: Month | B15: Collections | C15: Outstanding | D15: Transactions
A16: 45962 | B16: =SUMIF(DATA_RECEIPTS!$A$6:$A$75,A16,DATA_RECEIPTS!$E$6:$E$75) -> 7500 | C16: =SUMIF(DATA_RECEIPTS!$A$6:$A$75,A16,DATA_RECEIPTS!$F$6:$F$75) -> 0 | D16: =COUNTIF(DATA_RECEIPTS!$A$6:$A$75,A16) -> 8
A17: 46174 | B17: =SUMIF(DATA_RECEIPTS!$A$6:$A$75,A17,DATA_RECEIPTS!$E$6:$E$75) -> 700 | C17: =SUMIF(DATA_RECEIPTS!$A$6:$A$75,A17,DATA_RECEIPTS!$F$6:$F$75) -> 300 | D17: =COUNTIF(DATA_RECEIPTS!$A$6:$A$75,A17) -> 2
A18: 46204 | B18: =SUMIF(DATA_RECEIPTS!$A$6:$A$75,A18,DATA_RECEIPTS!$E$6:$E$75) -> 1600 | C18: =SUMIF(DATA_RECEIPTS!$A$6:$A$75,A18,DATA_RECEIPTS!$F$6:$F$75) -> 700 | D18: =COUNTIF(DATA_RECEIPTS!$A$6:$A$75,A18) -> 5
A19: 46235 | B19: =SUMIFS(DATA_RECEIPTS!E:E, DATA_RECEIPTS!A:A, ">=2026-08-01", DATA_RECEIPTS!A:A, "<2026-09-01") -> 4850 | C19: =SUMIF(DATA_RECEIPTS!$A$6:$A$75,A19,DATA_RECEIPTS!$F$6:$F$75) -> 2600 | D19: =COUNTIF(DATA_RECEIPTS!$A$6:$A$75,A19) -> 8
A20: 46266 | B20: =SUMIFS(DATA_RECEIPTS!E:E, DATA_RECEIPTS!A:A, ">=2026-09-01", DATA_RECEIPTS!A:A, "<2026-10-01") -> 2725 | C20: =SUMIF(DATA_RECEIPTS!$A$6:$A$75,A20,DATA_RECEIPTS!$F$6:$F$75) -> 2075 | D20: =COUNTIF(DATA_RECEIPTS!$A$6:$A$75,A20) -> 5

Sheet FINANCE
A1: FINANCE DASHBOARD
A2: Receipt book + expense book + bank reconciliation
A3: =HYPERLINK("#'HOME'!A1","HOME") -> HOME | B3: =HYPERLINK("#'FARMERS'!A1","FARMERS") -> FARMERS | C3: =HYPERLINK("#'SUBSCRIPTIONS'!A1","SUBSCRIPTIONS") -> SUBSCRIPTIONS | D3: =HYPERLINK("#'PRODUCTION'!A1","PRODUCTION") -> PRODUCTION | E3: =HYPERLINK("#'RECOVERY'!A1","RECOVERY") -> RECOVERY | F3: =HYPERLINK("#'DELIVERIES'!A1","DELIVERIES") -> DELIVERIES | G3: =HYPERLINK("#'FINANCE'!A1","FINANCE") -> FINANCE | H3: =HYPERLINK("#'REPORTS'!A1","REPORTS") -> REPORTS
A5: AUGUST TOTAL BANK RECEIPTS | C5: TOTAL BANK EXPENSES(YTD) | E5: CLOSING BANK BALANCE | G5: RECEIPT BOOK COLLECTIONS (YTD) | I5: SUBSCRIPTION OUTSTANDING | K5: RECONCILIATION STATUS
A6: =C14 -> 4850 | C6: =SUM(DATA_BANK!$D$6:$D$10) -> 13249.88 | E6: =E15 -> 4125.12 | G6: =SUM(DATA_RECEIPTS!$E$6:$E$75) -> 17375 | I6: =SUM(DATA_RECEIPTS!$F$6:$F$75) -> 14025 | K6: =COUNTIF(DATA_BANK!$H$6:$H$10,"RECONCILED") -> 5
A9: Monthly cash flow
A10: Month | B10: Opening | C10: Receipts | D10: Expenses | E10: Closing
A11: November 2025 | B11: =SUMIF(DATA_BANK!$A$6:$A$10,A11,DATA_BANK!$B$6:$B$10) -> 0 | C11: =SUMIF(DATA_BANK!$A$6:$A$10,A11,DATA_BANK!$C$6:$C$10) -> 7500 | D11: =SUMIF(DATA_BANK!$A$6:$A$10,A11,DATA_BANK!$D$6:$D$10) -> 7159.5 | E11: =SUMIF(DATA_BANK!$A$6:$A$10,A11,DATA_BANK!$E$6:$E$10) -> 340.5
A12: June 2026 | B12: =SUMIF(DATA_BANK!$A$6:$A$10,A12,DATA_BANK!$B$6:$B$10) -> 340.5 | C12: =SUMIF(DATA_BANK!$A$6:$A$10,A12,DATA_BANK!$C$6:$C$10) -> 700 | D12: =SUMIF(DATA_BANK!$A$6:$A$10,A12,DATA_BANK!$D$6:$D$10) -> 1300 | E12: =SUMIF(DATA_BANK!$A$6:$A$10,A12,DATA_BANK!$E$6:$E$10) -> -259.5
A13: July 2026 | B13: =SUMIF(DATA_BANK!$A$6:$A$10,A13,DATA_BANK!$B$6:$B$10) -> -259.5 | C13: =SUMIF(DATA_BANK!$A$6:$A$10,A13,DATA_BANK!$C$6:$C$10) -> 1600 | D13: =SUMIF(DATA_BANK!$A$6:$A$10,A13,DATA_BANK!$D$6:$D$10) -> 1832.98 | E13: =SUMIF(DATA_BANK!$A$6:$A$10,A13,DATA_BANK!$E$6:$E$10) -> -492.48
A14: August 2026 | B14: =SUMIF(DATA_BANK!$A$6:$A$10,A14,DATA_BANK!$B$6:$B$10) -> -492.48 | C14: =SUMIF(DATA_BANK!$A$6:$A$10,A14,DATA_BANK!$C$6:$C$10) -> 4850 | D14: =SUMIF(DATA_BANK!$A$6:$A$10,A14,DATA_BANK!$D$6:$D$10) -> 2491.31 | E14: =SUMIF(DATA_BANK!$A$6:$A$10,A14,DATA_BANK!$E$6:$E$10) -> 1866.21
A15: 46266 | B15: =E14 -> 1866.21 | C15: =DATA_BANK!C10 -> 2725 | D15: =DATA_BANK!D10 -> 466.09 | E15: =B15+C15-D15 -> 4125.12
A23: NEW MANAGEMENT ACCOUNTS | E23: Expense summary
A24: =HYPERLINK("#'MONTHLY SALARY'!A1","Monthly Salary") -> Monthly Salary | B24: Amount Paid | C24: =HYPERLINK("#'PROFIT & LOSS'!A1","Profit & Loss") -> Profit & Loss | E24: =HYPERLINK("#'BALANCE SHEET'!A1","Balance Sheet") -> Balance Sheet | F24: Expense
A25: Bank | B25: =SUMIF(DATA_RECEIPTS!$G$6:$G$75,A25,DATA_RECEIPTS!$E$6:$E$75) -> 3650 | E25: November 2025 | F25: =SUMIF(DATA_BANK!$A$6:$A$10,E25,DATA_BANK!$D$6:$D$10) -> 7159.5
A26: Cash | B26: =SUMIF(DATA_RECEIPTS!$G$6:$G$75,A26,DATA_RECEIPTS!$E$6:$E$75) -> 8400 | E26: June 2026 | F26: =SUMIF(DATA_BANK!$A$6:$A$10,E26,DATA_BANK!$D$6:$D$10) -> 1300
E27: July 2026 | F27: =SUMIF(DATA_BANK!$A$6:$A$10,E27,DATA_BANK!$D$6:$D$10) -> 1832.98
E28: August 2026 | F28: =SUMIF(DATA_BANK!$A$6:$A$10,E28,DATA_BANK!$D$6:$D$10) -> 2491.31
E29: 46266 | F29: =D15 -> 466.09

Sheet CLUSTER PERFORMANCE
A1: SGR 200HA+ CLUB | CLUSTER PERFORMANCE | N1: =HYPERLINK("#'DATA_PIPELINE'!A1","↗ DATA PIPELINE") -> ↗ DATA PIPELINE
A2: Live management view linked directly to DATA_PIPELINE. Update DATA_PIPELINE and recalculate Excel to refresh the performance figures.
A4: TOTAL CLUSTERS | D4: TOTAL FARMERS | G4: TOTAL PIPELINE HA | J4: PAID FARMERS
A5: =COUNTA(A9:A196) -> 20 | D5: =SUM(B9:B196) -> 553 | G5: =SUM(E9:E196) -> 30096 | J5: =SUM(F9:F196) -> 55
A8: CLUSTER NAME | B8: FARMERS MANAGED | C8: MAIZE HA 2026/27 | D8: SORGHUM HA 2026/27 | E8: TOTAL PIPELINE HA | F8: PAID FARMERS | G8: UNPAID | H8: PAYMENT % | I8: PROVINCE | J8: DISTRICT | K8: CLUSTER CONTACT | L8: CONTACT DETAILS | M8: EXPECTED SUBSCRIPTIONS | N8: AMOUNT PAID
A9: BATSIRAYI MAGAYA | B9: =COUNTIF(DATA_PIPELINE!$D$5:$D$603,A9) -> 29 | C9: =SUMIF(DATA_PIPELINE!$D$5:$D$603,A9,DATA_PIPELINE!$M$5:$M$603) -> 70 | D9: =SUMIF(DATA_PIPELINE!$D$5:$D$603,A9,DATA_PIPELINE!$N$5:$N$603) -> 610 | E9: =C9+D9 -> 680 | F9: {=SUM(COUNTIFS(DATA_PIPELINE!$D$5:$D$603,A9,DATA_PIPELINE!$Y$5:$Y$603,{"Paid","Partly Paid"}))} -> 3 | G9: =B9-F9 -> 26 | H9: =IFERROR(F9/B9,0) -> 0.10344828 | I9: =IFERROR(_xlfn.single(_xlfn.xlookup(A9, DATA_PIPELINE!$D$5:$D$603, DATA_PIPELINE!$H$5:$H$603, "")), "") -> MASHWEST | J9: =IFERROR(_xlfn.single(_xlfn.xlookup(A9, DATA_PIPELINE!$D$5:$D$603, DATA_PIPELINE!$G$5:$G$603, "")), "") -> MAKONDE | K9: ='CLUSTER PERFORMANCE'!$A9 -> BATSIRAYI MAGAYA | L9: 0774798096 | M9: =SUMIF(DATA_PIPELINE!$D$5:$D$603,A9,DATA_PIPELINE!$V$5:$V$603) -> 14500 | N9: =SUMIF(DATA_PIPELINE!$D$5:$D$603,A9,DATA_PIPELINE!$W$5:$W$603) -> 650
A10: BETTY ZUNGUNDE | B10: =COUNTIF(DATA_PIPELINE!$D$5:$D$603,A10) -> 15 | C10: =SUMIF(DATA_PIPELINE!$D$5:$D$603,A10,DATA_PIPELINE!$M$5:$M$603) -> 10 | D10: =SUMIF(DATA_PIPELINE!$D$5:$D$603,A10,DATA_PIPELINE!$N$5:$N$603) -> 575 | E10: =C10+D10 -> 585 | F10: {=SUM(COUNTIFS(DATA_PIPELINE!$D$5:$D$603,A10,DATA_PIPELINE!$Y$5:$Y$603,{"Paid","Partly Paid"}))} -> 1 | G10: =B10-F10 -> 14 | H10: =IFERROR(F10/B10,0) -> 0.066666667 | I10: =IFERROR(_xlfn.single(_xlfn.xlookup(A10, DATA_PIPELINE!$D$5:$D$603, DATA_PIPELINE!$H$5:$H$603, "")), "") -> MASHWEST | J10: =IFERROR(_xlfn.single(_xlfn.xlookup(A10, DATA_PIPELINE!$D$5:$D$603, DATA_PIPELINE!$G$5:$G$603, "")), "") -> CHEGUTU | K10: ='CLUSTER PERFORMANCE'!$A10 -> BETTY ZUNGUNDE | L10: 0773868322 | M10: =SUMIF(DATA_PIPELINE!$D$5:$D$603,A10,DATA_PIPELINE!$V$5:$V$603) -> 7500 | N10: =SUMIF(DATA_PIPELINE!$D$5:$D$603,A10,DATA_PIPELINE!$W$5:$W$603) -> 50
A11: BLESSING CHIWERA | B11: =COUNTIF(DATA_PIPELINE!$D$5:$D$603,A11) -> 11 | C11: =SUMIF(DATA_PIPELINE!$D$5:$D$603,A11,DATA_PIPELINE!$M$5:$M$603) -> 2605 | D11: =SUMIF(DATA_PIPELINE!$D$5:$D$603,A11,DATA_PIPELINE!$N$5:$N$603) -> 0 | E11: =C11+D11 -> 2605 | F11: {=SUM(COUNTIFS(DATA_PIPELINE!$D$5:$D$603,A11,DATA_PIPELINE!$Y$5:$Y$603,{"Paid","Partly Paid"}))} -> 0 | G11: =B11-F11 -> 11 | H11: =IFERROR(F11/B11,0) -> 0 | I11: =IFERROR(_xlfn.single(_xlfn.xlookup(A11, DATA_PIPELINE!$D$5:$D$603, DATA_PIPELINE!$H$5:$H$603, "")), "") -> MASHWEST | J11: =IFERROR(_xlfn.single(_xlfn.xlookup(A11, DATA_PIPELINE!$D$5:$D$603, DATA_PIPELINE!$G$5:$G$603, "")), "") -> NK | K11: ='CLUSTER PERFORMANCE'!$A11 -> BLESSING CHIWERA | L11: 0772714503 | M11: =SUMIF(DATA_PIPELINE!$D$5:$D$603,A11,DATA_PIPELINE!$V$5:$V$603) -> 6500 | N11: =SUMIF(DATA_PIPELINE!$D$5:$D$603,A11,DATA_PIPELINE!$W$5:$W$603) -> 0
A12: BRIAN CHIDAVAENZI | B12: =COUNTIF(DATA_PIPELINE!$D$5:$D$603,A12) -> 18 | C12: =SUMIF(DATA_PIPELINE!$D$5:$D$603,A12,DATA_PIPELINE!$M$5:$M$603) -> 10 | D12: =SUMIF(DATA_PIPELINE!$D$5:$D$603,A12,DATA_PIPELINE!$N$5:$N$603) -> 1070 | E12: =C12+D12 -> 1080 | F12: {=SUM(COUNTIFS(DATA_PIPELINE!$D$5:$D$603,A12,DATA_PIPELINE!$Y$5:$Y$603,{"Paid","Partly Paid"}))} -> 0 | G12: =B12-F12 -> 18 | H12: =IFERROR(F12/B12,0) -> 0 | I12: =IFERROR(_xlfn.single(_xlfn.xlookup(A12, DATA_PIPELINE!$D$5:$D$603, DATA_PIPELINE!$H$5:$H$603, "")), "") -> MASHWEST | J12: =IFERROR(_xlfn.single(_xlfn.xlookup(A12, DATA_PIPELINE!$D$5:$D$603, DATA_PIPELINE!$G$5:$G$603, "")), "") -> HURUNGWE | K12: ='CLUSTER PERFORMANCE'!$A12 -> BRIAN CHIDAVAENZI | L12: 0774346142 | M12: =SUMIF(DATA_PIPELINE!$D$5:$D$603,A12,DATA_PIPELINE!$V$5:$V$603) -> 10500 | N12: =SUMIF(DATA_PIPELINE!$D$5:$D$603,A12,DATA_PIPELINE!$W$5:$W$603) -> 0
A13: COMMENT TONDERAYI MUTARA | B13: =COUNTIF(DATA_PIPELINE!$D$5:$D$603,A13) -> 64 | C13: =SUMIF(DATA_PIPELINE!$D$5:$D$603,A13,DATA_PIPELINE!$M$5:$M$603) -> 252 | D13: =SUMIF(DATA_PIPELINE!$D$5:$D$603,A13,DATA_PIPELINE!$N$5:$N$603) -> 2549 | E13: =C13+D13 -> 2801 | F13: {=SUM(COUNTIFS(DATA_PIPELINE!$D$5:$D$603,A13,DATA_PIPELINE!$Y$5:$Y$603,{"Paid","Partly Paid"}))} -> 8 | G13: =B13-F13 -> 56 | H13: =IFERROR(F13/B13,0) -> 0.125 | I13: =IFERROR(_xlfn.single(_xlfn.xlookup(A13, DATA_PIPELINE!$D$5:$D$603, DATA_PIPELINE!$H$5:$H$603, "")), "") -> MASHWEST | J13: =IFERROR(_xlfn.single(_xlfn.xlookup(A13, DATA_PIPELINE!$D$5:$D$603, DATA_PIPELINE!$G$5:$G$603, "")), "") -> HURUNGWE | K13: ='CLUSTER PERFORMANCE'!$A13 -> COMMENT TONDERAYI MUTARA | L13: 0774117214 | M13: =SUMIF(DATA_PIPELINE!$D$5:$D$603,A13,DATA_PIPELINE!$V$5:$V$603) -> 32500 | N13: =SUMIF(DATA_PIPELINE!$D$5:$D$603,A13,DATA_PIPELINE!$W$5:$W$603) -> 2800
A14: DANMORE MUDAVANHU | B14: =COUNTIF(DATA_PIPELINE!$D$5:$D$603,A14) -> 35 | C14: =SUMIF(DATA_PIPELINE!$D$5:$D$603,A14,DATA_PIPELINE!$M$5:$M$603) -> 1086 | D14: =SUMIF(DATA_PIPELINE!$D$5:$D$603,A14,DATA_PIPELINE!$N$5:$N$603) -> 1213 | E14: =C14+D14 -> 2299 | F14: {=SUM(COUNTIFS(DATA_PIPELINE!$D$5:$D$603,A14,DATA_PIPELINE!$Y$5:$Y$603,{"Paid","Partly Paid"}))} -> 1 | G14: =B14-F14 -> 34 | H14: =IFERROR(F14/B14,0) -> 0.028571429 | I14: =IFERROR(_xlfn.single(_xlfn.xlookup(A14, DATA_PIPELINE!$D$5:$D$603, DATA_PIPELINE!$H$5:$H$603, "")), "") -> MASHWEST | J14: =IFERROR(_xlfn.single(_xlfn.xlookup(A14, DATA_PIPELINE!$D$5:$D$603, DATA_PIPELINE!$G$5:$G$603, "")), "") -> CHEGUTU | K14: ='CLUSTER PERFORMANCE'!$A14 -> DANMORE MUDAVANHU | L14: 0772960915 | M14: =SUMIF(DATA_PIPELINE!$D$5:$D$603,A14,DATA_PIPELINE!$V$5:$V$603) -> 18000 | N14: =SUMIF(DATA_PIPELINE!$D$5:$D$603,A14,DATA_PIPELINE!$W$5:$W$603) -> 100
A15: JAMES MASANGO | B15: =COUNTIF(DATA_PIPELINE!$D$5:$D$603,A15) -> 4 | C15: =SUMIF(DATA_PIPELINE!$D$5:$D$603,A15,DATA_PIPELINE!$M$5:$M$603) -> 0 | D15: =SUMIF(DATA_PIPELINE!$D$5:$D$603,A15,DATA_PIPELINE!$N$5:$N$603) -> 95 | E15: =C15+D15 -> 95 | F15: {=SUM(COUNTIFS(DATA_PIPELINE!$D$5:$D$603,A15,DATA_PIPELINE!$Y$5:$Y$603,{"Paid","Partly Paid"}))} -> 1 | G15: =B15-F15 -> 3 | H15: =IFERROR(F15/B15,0) -> 0.25 | I15: =IFERROR(_xlfn.single(_xlfn.xlookup(A15, DATA_PIPELINE!$D$5:$D$603, DATA_PIPELINE!$H$5:$H$603, "")), "") -> MASHWEST | J15: =IFERROR(_xlfn.single(_xlfn.xlookup(A15, DATA_PIPELINE!$D$5:$D$603, DATA_PIPELINE!$G$5:$G$603, "")), "") -> MAKONDE | K15: ='CLUSTER PERFORMANCE'!$A15 -> JAMES MASANGO | L15: 0772854734 | M15: =SUMIF(DATA_PIPELINE!$D$5:$D$603,A15,DATA_PIPELINE!$V$5:$V$603) -> 2000 | N15: =SUMIF(DATA_PIPELINE!$D$5:$D$603,A15,DATA_PIPELINE!$W$5:$W$603) -> 50
